Workbook

Sheet Описание полей
B3: Поля в "Список тестов" | C3: Описание
B4: N | C4: Порядковый номер теста
B5: N_REQ | C5: Порядковый номер теста в пределах обработчика
B6: TEST_ID | C6: Идентификатор теста
B7: REQUEST | C7: Обработчик
B8: GROUP | C8: Группа теста (см. Описание значений)
B9: TYPE | C9: Тип теста (см. Описание значений)
B10: INSTANCE | C10: Порядковый номер теста в пределах типа
B11: GROUP_DESCRIPTION | C11: Описание группы теста
B12: TYPE_DESCRIPTION | C12: Описание типа теста
B13: INSTANCE_DESCRIPTION | C13: Описание конкретного теста
B14: WITH_FILE | C14: Используется файл (boolean)
... B32: duration_in_seconds | C32: Длительность выполнения обработки (в секундах)

Sheet Описание значений
B3: REQUEST | C3: Порядковый номер
B4: POST data | C4: 01
B5: PATCH data | C5: 02
B6: GET data | C6: 03
B7: GET birthdays | C7: 04
B8: GET percentiles | C8: 05
B11: GROUP | C11: Описание
B12: 00 | C12: Верный запрос
B13: 01 | C13: Общая ошибка в формате входных данных
B14: 02 | C14: Нет необходимых полей во входных данных
B15: 03 | C15: Лишние поля во входных данных
B16: 04 | C16: Ошибка в значениях во входных данных
... B39: 06t02 | C39: Отсутствует указанный citizen_id

Sheet Список тестов
A1: N | B1: N_REQ | C1: TEST_ID | D1: REQUEST | E1: GROUP | F1: TYPE | G1: INSTANCE | H1: GROUP_DESCRIPTION | I1: TYPE_DESCRIPTION | J1: INSTANCE_DESCRIPTION | K1: WITH_FILE | L1: FILE_NAME | M1: CURL_REQUEST | N1: EXPECTED_STATUS | O1: RESPONSE_STATUS | P1: PASSED | Q1: RESPONSE_DETAIL | R1: RESPONSE_TIME
A2: 1 | B2: 1 | C2: ="R"&VLOOKUP(D2,'Описание значений'!$B$4:$C$8,2,FALSE)&"_G"&F2&"_N"&TEXT(G2,"00") -> R01_G00t01_N01 | D2: POST data | E2: 00 | F2: 00t01 | G2: 1 | H2: =VLOOKUP(E2,'Описание значений'!$B$11:$C$18,2,FALSE) -> Верный запрос | I2: =VLOOKUP(F2,'Описание значений'!$B$21:$C$39,2,FALSE) -> Верный запрос | J2: Данные горожан в правильном формате, 1 гражданин | K2: 1 | L2: ="Testing/Data_to_import/"&LEFT(D2,SEARCH(" ",D2)-1)&"/cit1.json" -> Testing/Data_to_import/POST/cit1.json | M2: ="curl -X POST -d ""@"&L2&""" 0.0.0.0:8080/imports" -> curl -X POST -d "@Testing/Data_to_import/POST/cit1.json" 0.0.0.0:8080/imports | N2: 201 | O2: =LOGS!F2 -> 201 | P2: =IF(O2=N2,"OK","FAIL") -> OK | Q2: =LOGS!G2 -> {'import_id': 1} | R2: =LOGS!H2 -> 0.035671 | AC2: .
A3: 2 | B3: 2 | C3: ="R"&VLOOKUP(D3,'Описание значений'!$B$4:$C$8,2,FALSE)&"_G"&F3&"_N"&TEXT(G3,"00") -> R01_G00t01_N02 | D3: POST data | E3: 00 | F3: 00t01 | G3: 2 | H3: =VLOOKUP(E3,'Описание значений'!$B$11:$C$18,2,FALSE) -> Верный запрос | I3: =VLOOKUP(F3,'Описание значений'!$B$21:$C$39,2,FALSE) -> Верный запрос | J3: Данные горожан в правильном формате, 10 граждан | K3: 1 | L3: ="Testing/Data_to_import/"&LEFT(D3,SEARCH(" ",D3)-1)&"/cit10.json" -> Testing/Data_to_import/POST/cit10.json | M3: ="curl -X POST -d ""@"&L3&""" 0.0.0.0:8080/imports" -> curl -X POST -d "@Testing/Data_to_import/POST/cit10.json" 0.0.0.0:8080/imports | N3: 201 | O3: =LOGS!F3 -> 201 | P3: =IF(O3=N3,"OK","FAIL") -> OK | Q3: =LOGS!G3 -> {'import_id': 2} | R3: =LOGS!H3 -> 0.04336
A4: 3 | B4: 3 | C4: ="R"&VLOOKUP(D4,'Описание значений'!$B$4:$C$8,2,FALSE)&"_G"&F4&"_N"&TEXT(G4,"00") -> R01_G00t01_N03 | D4: POST data | E4: 00 | F4: 00t01 | G4: 3 | H4: =VLOOKUP(E4,'Описание значений'!$B$11:$C$18,2,FALSE) -> Верный запрос | I4: =VLOOKUP(F4,'Описание значений'!$B$21:$C$39,2,FALSE) -> Верный запрос | J4: Данные горожан в правильном формате, 100 граждан | K4: 1 | L4: ="Testing/Data_to_import/"&LEFT(D4,SEARCH(" ",D4)-1)&"/cit100.json" -> Testing/Data_to_import/POST/cit100.json | M4: ="curl -X POST -d ""@"&L4&""" 0.0.0.0:8080/imports" -> curl -X POST -d "@Testing/Data_to_import/POST/cit100.json" 0.0.0.0:8080/imports | N4: 201 | O4: =LOGS!F4 -> 201 | P4: =IF(O4=N4,"OK","FAIL") -> OK | Q4: =LOGS!G4 -> {'import_id': 3} | R4: =LOGS!H4 -> 0.068024
A5: 4 | B5: 4 | C5: ="R"&VLOOKUP(D5,'Описание значений'!$B$4:$C$8,2,FALSE)&"_G"&F5&"_N"&TEXT(G5,"00") -> R01_G00t01_N04 | D5: POST data | E5: 00 | F5: 00t01 | G5: 4 | H5: =VLOOKUP(E5,'Описание значений'!$B$11:$C$18,2,FALSE) -> Верный запрос | I5: =VLOOKUP(F5,'Описание значений'!$B$21:$C$39,2,FALSE) -> Верный запрос | J5: Данные горожан в правильном формате, 1000 граждан | K5: 1 | L5: ="Testing/Data_to_import/"&LEFT(D5,SEARCH(" ",D5)-1)&"/cit1000.json" -> Testing/Data_to_import/POST/cit1000.json | M5: ="curl -X POST -d ""@"&L5&""" 0.0.0.0:8080/imports" -> curl -X POST -d "@Testing/Data_to_import/POST/cit1000.json" 0.0.0.0:8080/imports | N5: 201 | O5: =LOGS!F5 -> 201 | P5: =IF(O5=N5,"OK","FAIL") -> OK | Q5: =LOGS!G5 -> {'import_id': 4} | R5: =LOGS!H5 -> 0.135905
A6: 5 | B6: 5 | C6: ="R"&VLOOKUP(D6,'Описание значений'!$B$4:$C$8,2,FALSE)&"_G"&F6&"_N"&TEXT(G6,"00") -> R01_G00t01_N05 | D6: POST data | E6: 00 | F6: 00t01 | G6: 5 | H6: =VLOOKUP(E6,'Описание значений'!$B$11:$C$18,2,FALSE) -> Верный запрос | I6: =VLOOKUP(F6,'Описание значений'!$B$21:$C$39,2,FALSE) -> Верный запрос | J6: Данные горожан в правильном формате, 10000 граждан | K6: 1 | L6: ="Testing/Data_to_import/"&LEFT(D6,SEARCH(" ",D6)-1)&"/cit10000.json" -> Testing/Data_to_import/POST/cit10000.json | M6: ="curl -X POST -d ""@"&L6&""" 0.0.0.0:8080/imports" -> curl -X POST -d "@Testing/Data_to_import/POST/cit10000.json" 0.0.0.0:8080/imports | N6: 201 | O6: =LOGS!F6 -> 201 | P6: =IF(O6=N6,"OK","FAIL") -> OK | Q6: =LOGS!G6 -> {'import_id': 5} | R6: =LOGS!H6 -> 0.760596
A7: 6 | B7: 6 | C7: ="R"&VLOOKUP(D7,'Описание значений'!$B$4:$C$8,2,FALSE)&"_G"&F7&"_N"&TEXT(G7,"00") -> R01_G00t01_N06 | D7: POST data | E7: 00 | F7: 00t01 | G7: 6 | H7: =VLOOKUP(E7,'Описание значений'!$B$11:$C$18,2,FALSE) -> Верный запрос | I7: =VLOOKUP(F7,'Описание значений'!$B$21:$C$39,2,FALSE) -> Верный запрос | J7: Данные горожан в правильном формате, 50000 граждан | K7: 1 | L7: ="Testing/Data_to_import/"&LEFT(D7,SEARCH(" ",D7)-1)&"/cit50000.json" -> Testing/Data_to_import/POST/cit50000.json | M7: ="curl -X POST -d ""@"&L7&""" 0.0.0.0:8080/imports" -> curl -X POST -d "@Testing/Data_to_import/POST/cit50000.json" 0.0.0.0:8080/imports | N7: 201 | O7: =LOGS!F7 -> 201 | P7: =IF(O7=N7,"OK","FAIL") -> OK | Q7: =LOGS!G7 -> {'import_id': 6} | R7: =LOGS!H7 -> 3.311517
A8: 7 | B8: 7 | C8: ="R"&VLOOKUP(D8,'Описание значений'!$B$4:$C$8,2,FALSE)&"_G"&F8&"_N"&TEXT(G8,"00") -> R01_G01t01_N01 | D8: POST data | E8: 01 | F8: 01t01 | G8: 1 | H8: =VLOOKUP(E8,'Описание значений'!$B$11:$C$18,2,FALSE) -> Общая ошибка в формате входных данных | I8: =VLOOKUP(F8,'Описание значений'!$B$21:$C$39,2,FALSE) -> Формат входных данных не JSON | J8: Формат не JSON: отсутствует закрывающая скобка | K8: 1 | L8: ="Testing/Data_to_import/"&LEFT(D8,SEARCH(" ",D8)-1)&"/d"&B8&".json" -> Testing/Data_to_import/POST/d7.json | M8: ="curl -X POST -d ""@"&L8&""" 0.0.0.0:8080/imports" -> curl -X POST -d "@Testing/Data_to_import/POST/d7.json" 0.0.0.0:8080/imports | N8: 400 | O8: =LOGS!F8 -> 400 | P8: =IF(O8=N8,"OK","FAIL") -> OK | Q8: =LOGS!G8 -> Import data is not in JSON format | R8: =LOGS!H8 -> 0.001024
A9: 8 | B9: 8 | C9: ="R"&VLOOKUP(D9,'Описание значений'!$B$4:$C$8,2,FALSE)&"_G"&F9&"_N"&TEXT(G9,"00") -> R01_G01t01_N02 | D9: POST data | E9: 01 | F9: 01t01 | G9: 2 | H9: =VLOOKUP(E9,'Описание значений'!$B$11:$C$18,2,FALSE) -> Общая ошибка в формате входных данных | I9: =VLOOKUP(F9,'Описание значений'!$B$21:$C$39,2,FALSE) -> Формат входных данных не JSON | J9: Формат не JSON: ключ "town" без значения | K9: 1 | L9: ="Testing/Data_to_import/"&LEFT(D9,SEARCH(" ",D9)-1)&"/d"&B9&".json" -> Testing/Data_to_import/POST/d8.json | M9: ="curl -X POST -d ""@"&L9&""" 0.0.0.0:8080/imports" -> curl -X POST -d "@Testing/Data_to_import/POST/d8.json" 0.0.0.0:8080/imports | N9: 400 | O9: =LOGS!F9 -> 400 | P9: =IF(O9=N9,"OK","FAIL") -> OK | Q9: =LOGS!G9 -> Import data is not in JSON format | R9: =LOGS!H9 -> 0.000794
A10: 9 | B10: 9 | C10: ="R"&VLOOKUP(D10,'Описание значений'!$B$4:$C$8,2,FALSE)&"_G"&F10&"_N"&TEXT(G10,"00") -> R01_G01t01_N03 | D10: POST data | E10: 01 | F10: 01t01 | G10: 3 | H10: =VLOOKUP(E10,'Описание значений'!$B$11:$C$18,2,FALSE) -> Общая ошибка в формате входных данных | I10: =VLOOKUP(F10,'Описание значений'!$B$21:$C$39,2,FALSE) -> Формат входных данных не JSON | J10: Формат не JSON: значение birth_dt в одинарных кавычках | K10: 1 | L10: ="Testing/Data_to_import/"&LEFT(D10,SEARCH(" ",D10)-1)&"/d"&B10&".json" -> Testing/Data_to_import/POST/d9.json | M10: ="curl -X POST -d ""@"&L10&""" 0.0.0.0:8080/imports" -> curl -X POST -d "@Testing/Data_to_import/POST/d9.json" 0.0.0.0:8080/imports | N10: 400 | O10: =LOGS!F10 -> 400 | P10: =IF(O10=N10,"OK","FAIL") -> OK | Q10: =LOGS!G10 -> Import data is not in JSON format | R10: =LOGS!H10 -> 0.000997
A11: 10 | B11: 10 | C11: ="R"&VLOOKUP(D11,'Описание значений'!$B$4:$C$8,2,FALSE)&"_G"&F11&"_N"&TEXT(G11,"00") -> R01_G01t02_N04 | D11: POST data | E11: 01 | F11: 01t02 | G11: 4 | H11: =VLOOKUP(E11,'Описание значений'!$B$11:$C$18,2,FALSE) -> Общая ошибка в формате входных данных | I11: =VLOOKUP(F11,'Описание значений'!$B$21:$C$39,2,FALSE) -> Ошибка в структуре входных данных | J11: На первом уровне есть лишняя пара (помимо "citizens":[]) | K11: 1 | L11: ="Testing/Data_to_import/"&LEFT(D11,SEARCH(" ",D11)-1)&"/d"&B11&".json" -> Testing/Data_to_import/POST/d10.json | M11: ="curl -X POST -d ""@"&L11&""" 0.0.0.0:8080/imports" -> curl -X POST -d "@Testing/Data_to_import/POST/d10.json" 0.0.0.0:8080/imports | N11: 400 | O11: =LOGS!F11 -> 400 | P11: =IF(O11=N11,"OK","FAIL") -> OK | Q11: =LOGS!G11 -> Import data has more than 1 key (should be only "citizens") | R11: =LOGS!H11 -> 0.001014
A12: 11 | B12: 11 | C12: ="R"&VLOOKUP(D12,'Описание значений'!$B$4:$C$8,2,FALSE)&"_G"&F12&"_N"&TEXT(G12,"00") -> R01_G01t02_N05 | D12: POST data | E12: 01 | F12: 01t02 | G12: 5 | H12: =VLOOKUP(E12,'Описание значений'!$B$11:$C$18,2,FALSE) -> Общая ошибка в формате входных данных | I12: =VLOOKUP(F12,'Описание значений'!$B$21:$C$39,2,FALSE) -> Ошибка в структуре входных данных | J12: На первом уровне нет пары "citizens":[] | K12: 1 | L12: ="Testing/Data_to_import/"&LEFT(D12,SEARCH(" ",D12)-1)&"/d"&B12&".json" -> Testing/Data_to_import/POST/d11.json | M12: ="curl -X POST -d ""@"&L12&""" 0.0.0.0:8080/imports" -> curl -X POST -d "@Testing/Data_to_import/POST/d11.json" 0.0.0.0:8080/imports | N12: 400 | O12: =LOGS!F12 -> 400 | P12: =IF(O12=N12,"OK","FAIL") -> OK | Q12: =LOGS!G12 -> Import data has no "citizens" key | R12: =LOGS!H12 -> 0.001191
A13: 12 | B13: 12 | C13: ="R"&VLOOKUP(D13,'Описание значений'!$B$4:$C$8,2,FALSE)&"_G"&F13&"_N"&TEXT(G13,"00") -> R01_G01t02_N06 | D13: POST data | E13: 01 | F13: 01t02 | G13: 6 | H13: =VLOOKUP(E13,'Описание значений'!$B$11:$C$18,2,FALSE) -> Общая ошибка в формате входных данных | I13: =VLOOKUP(F13,'Описание значений'!$B$21:$C$39,2,FALSE) -> Ошибка в структуре входных данных | J13: Присутствует дублирование ключа citizens (на первом уровне) | K13: 1 | L13: ="Testing/Data_to_import/"&LEFT(D13,SEARCH(" ",D13)-1)&"/d"&B13&".json" -> Testing/Data_to_import/POST/d12.json | M13: ="curl -X POST -d ""@"&L13&""" 0.0.0.0:8080/imports" -> curl -X POST -d "@Testing/Data_to_import/POST/d12.json" 0.0.0.0:8080/imports | N13: 400 | O13: =LOGS!F13 -> 400 | P13: =IF(O13=N13,"OK","FAIL") -> OK | Q13: =LOGS!G13 -> Import data has duplicate keys | R13: =LOGS!H13 -> 0.001152
A14: 13 | B14: 13 | C14: ="R"&VLOOKUP(D14,'Описание значений'!$B$4:$C$8,2,FALSE)&"_G"&F14&"_N"&TEXT(G14,"00") -> R01_G01t02_N07 | D14: POST data | E14: 01 | F14: 01t02 | G14: 7 | H14: =VLOOKUP(E14,'Описание значений'!$B$11:$C$18,2,FALSE) -> Общая ошибка в формате входных данных | I14: =VLOOKUP(F14,'Описание значений'!$B$21:$C$39,2,FALSE) -> Ошибка в структуре входных данных | J14: Присутствует дублирование ключа name (внутри списка citizens) | K14: 1 | L14: ="Testing/Data_to_import/"&LEFT(D14,SEARCH(" ",D14)-1)&"/d"&B14&".json" -> Testing/Data_to_import/POST/d13.json | M14: ="curl -X POST -d ""@"&L14&""" 0.0.0.0:8080/imports" -> curl -X POST -d "@Testing/Data_to_import/POST/d13.json" 0.0.0.0:8080/imports | N14: 400 | O14: =LOGS!F14 -> 400 | P14: =IF(O14=N14,"OK","FAIL") -> OK | Q14: =LOGS!G14 -> Import data has duplicate keys | R14: =LOGS!H14 -> 0.000901
A15: 14 | B15: 14 | C15: ="R"&VLOOKUP(D15,'Описание значений'!$B$4:$C$8,2,FALSE)&"_G"&F15&"_N"&TEXT(G15,"00") -> R01_G01t02_N08 | D15: POST data | E15: 01 | F15: 01t02 | G15: 8 | H15: =VLOOKUP(E15,'Описание значений'!$B$11:$C$18,2,FALSE) -> Общая ошибка в формате входных данных | I15: =VLOOKUP(F15,'Описание значений'!$B$21:$C$39,2,FALSE) -> Ошибка в структуре входных данных | J15: Значение citizens не является списком | K15: 1 | L15: ="Testing/Data_to_import/"&LEFT(D15,SEARCH(" ",D15)-1)&"/d"&B15&".json" -> Testing/Data_to_import/POST/d14.json | M15: ="curl -X POST -d ""@"&L15&""" 0.0.0.0:8080/imports" -> curl -X POST -d "@Testing/Data_to_import/POST/d14.json" 0.0.0.0:8080/imports | N15: 400 | O15: =LOGS!F15 -> 400 | P15: =IF(O15=N15,"OK","FAIL") -> OK | Q15: =LOGS!G15 -> The "citizens" value must be a list | R15: =LOGS!H15 -> 0.001112
A16: 15 | B16: 15 | C16: ="R"&VLOOKUP(D16,'Описание значений'!$B$4:$C$8,2,FALSE)&"_G"&F16&"_N"&TEXT(G16,"00") -> R01_G01t02_N09 | D16: POST data | E16: 01 | F16: 01t02 | G16: 9 | H16: =VLOOKUP(E16,'Описание значений'!$B$11:$C$18,2,FALSE) -> Общая ошибка в формате входных данных | I16: =VLOOKUP(F16,'Описание значений'!$B$21:$C$39,2,FALSE) -> Ошибка в структуре входных данных | J16: Значение citizens является пустым списком | K16: 1 | L16: ="Testing/Data_to_import/"&LEFT(D16,SEARCH(" ",D16)-1)&"/d"&B16&".json" -> Testing/Data_to_import/POST/d15.json | M16: ="curl -X POST -d ""@"&L16&""" 0.0.0.0:8080/imports" -> curl -X POST -d "@Testing/Data_to_import/POST/d15.json" 0.0.0.0:8080/imports | N16: 400 | O16: =LOGS!F16 -> 400 | P16: =IF(O16=N16,"OK","FAIL") -> OK | Q16: =LOGS!G16 -> No citizens in import data. Should be at least one | R16: =LOGS!H16 -> 0.001138
A17: 16 | B17: 16 | C17: ="R"&VLOOKUP(D17,'Описание значений'!$B$4:$C$8,2,FALSE)&"_G"&F17&"_N"&TEXT(G17,"00") -> R01_G02t01_N01 | D17: POST data | E17: 02 | F17: 02t01 | G17: 1 | H17: =VLOOKUP(E17,'Описание значений'!$B$11:$C$18,2,FALSE) -> Нет необходимых полей во входных данных | I17: =VLOOKUP(F17,'Описание значений'!$B$21:$C$39,2,FALSE) -> Отсутствует одно поле | J17: Отсутствует поле citizen_id у одного гражданина | K17: 1 | L17: ="Testing/Data_to_import/"&LEFT(D17,SEARCH(" ",D17)-1)&"/d"&B17&".json" -> Testing/Data_to_import/POST/d16.json | M17: ="curl -X POST -d ""@"&L17&""" 0.0.0.0:8080/imports" -> curl -X POST -d "@Testing/Data_to_import/POST/d16.json" 0.0.0.0:8080/imports | N17: 400 | O17: =LOGS!F17 -> 400 | P17: =IF(O17=N17,"OK","FAIL") -> OK | Q17: =LOGS!G17 -> One or more fields are missing in import data - key citizen_id (citizen 0) | R17: =LOGS!H17 -> 0.00099
A18: 17 | B18: 17 | C18: ="R"&VLOOKUP(D18,'Описание значений'!$B$4:$C$8,2,FALSE)&"_G"&F18&"_N"&TEXT(G18,"00") -> R01_G02t01_N02 | D18: POST data | E18: 02 | F18: 02t01 | G18: 2 | H18: =VLOOKUP(E18,'Описание значений'!$B$11:$C$18,2,FALSE) -> Нет необходимых полей во входных данных | I18: =VLOOKUP(F18,'Описание значений'!$B$21:$C$39,2,FALSE) -> Отсутствует одно поле | J18: Отсутствует поле birth_date у нескольких граждан | K18: 1 | L18: ="Testing/Data_to_import/"&LEFT(D18,SEARCH(" ",D18)-1)&"/d"&B18&".json" -> Testing/Data_to_import/POST/d17.json | M18: ="curl -X POST -d ""@"&L18&""" 0.0.0.0:8080/imports" -> curl -X POST -d "@Testing/Data_to_import/POST/d17.json" 0.0.0.0:8080/imports | N18: 400 | O18: =LOGS!F18 -> 400 | P18: =IF(O18=N18,"OK","FAIL") -> OK | Q18: =LOGS!G18 -> One or more fields are missing in import data - key birth_date (citizen 0) | R18: =LOGS!H18 -> 0.001208
A19: 18 | B19: 18 | C19: ="R"&VLOOKUP(D19,'Описание значений'!$B$4:$C$8,2,FALSE)&"_G"&F19&"_N"&TEXT(G19,"00") -> R01_G02t01_N03 | D19: POST data | E19: 02 | F19: 02t01 | G19: 3 | H19: =VLOOKUP(E19,'Описание значений'!$B$11:$C$18,2,FALSE) -> Нет необходимых полей во входных данных | I19: =VLOOKUP(F19,'Описание значений'!$B$21:$C$39,2,FALSE) -> Отсутствует одно поле | J19: Отсутствует поле town у всех граждан | K19: 1 | L19: ="Testing/Data_to_import/"&LEFT(D19,SEARCH(" ",D19)-1)&"/d"&B19&".json" -> Testing/Data_to_import/POST/d18.json | M19: ="curl -X POST -d ""@"&L19&""" 0.0.0.0:8080/imports" -> curl -X POST -d "@Testing/Data_to_import/POST/d18.json" 0.0.0.0:8080/imports | N19: 400 | O19: =LOGS!F19 -> 400 | P19: =IF(O19=N19,"OK","FAIL") -> OK | Q19: =LOGS!G19 -> One or more fields are missing in import data - key town (citizen 0) | R19: =LOGS!H19 -> 0.001216
... A64: 63 | B64: 63 | C64: ="R"&VLOOKUP(D64,'Описание значений'!$B$4:$C$8,2,FALSE)&"_G"&F64&"_N"&TEXT(G64,"00") -> R01_G05t02_N05 | D64: POST data | E64: 05 | F64: 05t02 | G64: 5 | H64: =VLOOKUP(E64,'Описание значений'!$B$11:$C$18,2,FALSE) -> Ошибка в форматах во входных данных | I64: =VLOOKUP(F64,'Описание значений'!$B$21:$C$39,2,FALSE) -> Формат даты неверный (не ДД.ММ.ГГГГ) | J64: Дата 04.1978 | K64: 1 | L64: ="Testing/Data_to_import/"&LEFT(D64,SEARCH(" ",D64)-1)&"/d"&B64&".json" -> Testing/Data_to_import/POST/d63.json | M64: ="curl -X POST -d ""@"&L64&""" 0.0.0.0:8080/imports" -> curl -X POST -d "@Testing/Data_to_import/POST/d63.json" 0.0.0.0:8080/imports | N64: 400 | O64: =LOGS!F64 -> 400 | P64: =IF(O64=N64,"OK","FAIL") -> OK | Q64: =LOGS!G64 -> birth_date is invaild or has incorrect format, must be dd.mm.yyyy (citizen 4) | R64: =LOGS!H64 -> 0.001233
A65: 64 | B65: 1 | C65: ="R"&VLOOKUP(D65,'Описание значений'!$B$4:$C$8,2,FALSE)&"_G"&F65&"_N"&TEXT(G65,"00") -> R02_G00t01_N01 | D65: PATCH data | E65: 00 | F65: 00t01 | G65: 1 | H65: =VLOOKUP(E65,'Описание значений'!$B$11:$C$18,2,FALSE) -> Верный запрос | I65: =VLOOKUP(F65,'Описание значений'!$B$21:$C$39,2,FALSE) -> Верный запрос | J65: Изменение имени у citizen_id=1 | K65: 1 | L65: ="Testing/Data_to_import/"&LEFT(D65,SEARCH(" ",D65)-1)&"/d"&B65&".json" -> Testing/Data_to_import/PATCH/d1.json | M65: ="curl -X PATCH -d ""@"&L65&""" 0.0.0.0:8080/imports/2/citizens/1" -> curl -X PATCH -d "@Testing/Data_to_import/PATCH/d1.json" 0.0.0.0:8080/imports/2/citizens/1 | N65: 200 | O65: =LOGS!F65 -> 200 | P65: =IF(O65=N65,"OK","FAIL") -> OK | Q65: =LOGS!G65 -> {'citizen_id': 1, 'town': 'Мытищи', 'street': 'Макеевская улица', 'building': '70п69', 'apartment': 22, 'name': 'Измененное имя', 'birth_date': '16.11.1986', 'gender': 'male', 'relatives': [9, 2]} | R65: =LOGS!H65 -> 0.018354
A66: 65 | B66: 2 | C66: ="R"&VLOOKUP(D66,'Описание значений'!$B$4:$C$8,2,FALSE)&"_G"&F66&"_N"&TEXT(G66,"00") -> R02_G00t01_N02 | D66: PATCH data | E66: 00 | F66: 00t01 | G66: 2 | H66: =VLOOKUP(E66,'Описание значений'!$B$11:$C$18,2,FALSE) -> Верный запрос | I66: =VLOOKUP(F66,'Описание значений'!$B$21:$C$39,2,FALSE) -> Верный запрос | J66: Изменение родственных связей у citizen_id=1: relatives=[6,7] | K66: 1 | L66: ="Testing/Data_to_import/"&LEFT(D66,SEARCH(" ",D66)-1)&"/d"&B66&".json" -> Testing/Data_to_import/PATCH/d2.json | M66: ="curl -X PATCH -d ""@"&L66&""" 0.0.0.0:8080/imports/2/citizens/1" -> curl -X PATCH -d "@Testing/Data_to_import/PATCH/d2.json" 0.0.0.0:8080/imports/2/citizens/1 | N66: 200 | O66: =LOGS!F66 -> 200 | P66: =IF(O66=N66,"OK","FAIL") -> OK | Q66: =LOGS!G66 -> {'citizen_id': 1, 'town': 'Мытищи', 'street': 'Макеевская улица', 'building': '70п69', 'apartment': 22, 'name': 'Измененное имя', 'birth_date': '16.11.1986', 'gender': 'male', 'relatives': [6, 7]} | R66: =LOGS!H66 -> 0.082519
A67: 66 | B67: 3 | C67: ="R"&VLOOKUP(D67,'Описание значений'!$B$4:$C$8,2,FALSE)&"_G"&F67&"_N"&TEXT(G67,"00") -> R02_G00t01_N03 | D67: PATCH data | E67: 00 | F67: 00t01 | G67: 3 | H67: =VLOOKUP(E67,'Описание значений'!$B$11:$C$18,2,FALSE) -> Верный запрос | I67: =VLOOKUP(F67,'Описание значений'!$B$21:$C$39,2,FALSE) -> Верный запрос | J67: Удаление всех родственных связей у citizen_id=2 и изменение town | K67: 1 | L67: ="Testing/Data_to_import/"&LEFT(D67,SEARCH(" ",D67)-1)&"/d"&B67&".json" -> Testing/Data_to_import/PATCH/d3.json | M67: ="curl -X PATCH -d ""@"&L67&""" 0.0.0.0:8080/imports/2/citizens/2" -> curl -X PATCH -d "@Testing/Data_to_import/PATCH/d3.json" 0.0.0.0:8080/imports/2/citizens/2 | N67: 200 | O67: =LOGS!F67 -> 200 | P67: =IF(O67=N67,"OK","FAIL") -> OK | Q67: =LOGS!G67 -> {'citizen_id': 1, 'town': 'Измененный город', 'street': 'Макеевская улица', 'building': '70п69', 'apartment': 22, 'name': 'Измененное имя', 'birth_date': '16.11.1986', 'gender': 'male', 'relatives': []} | R67: =LOGS!H67 -> 0.031276
A68: 67 | B68: 4 | C68: ="R"&VLOOKUP(D68,'Описание значений'!$B$4:$C$8,2,FALSE)&"_G"&F68&"_N"&TEXT(G68,"00") -> R02_G01t01_N01 | D68: PATCH data | E68: 01 | F68: 01t01 | G68: 1 | H68: =VLOOKUP(E68,'Описание значений'!$B$11:$C$18,2,FALSE) -> Общая ошибка в формате входных данных | I68: =VLOOKUP(F68,'Описание значений'!$B$21:$C$39,2,FALSE) -> Формат входных данных не JSON | J68: Круглые скобки вместо фигурных | K68: 1 | L68: ="Testing/Data_to_import/"&LEFT(D68,SEARCH(" ",D68)-1)&"/d"&B68&".json" -> Testing/Data_to_import/PATCH/d4.json | M68: ="curl -X PATCH -d ""@"&L68&""" 0.0.0.0:8080/imports/2/citizens/1" -> curl -X PATCH -d "@Testing/Data_to_import/PATCH/d4.json" 0.0.0.0:8080/imports/2/citizens/1 | N68: 400 | O68: =LOGS!F68 -> 400 | P68: =IF(O68=N68,"OK","FAIL") -> OK | Q68: =LOGS!G68 -> Import data is not in JSON format | R68: =LOGS!H68 -> 0.000905
A69: 68 | B69: 5 | C69: ="R"&VLOOKUP(D69,'Описание значений'!$B$4:$C$8,2,FALSE)&"_G"&F69&"_N"&TEXT(G69,"00") -> R02_G01t01_N02 | D69: PATCH data | E69: 01 | F69: 01t01 | G69: 2 | H69: =VLOOKUP(E69,'Описание значений'!$B$11:$C$18,2,FALSE) -> Общая ошибка в формате входных данных | I69: =VLOOKUP(F69,'Описание значений'!$B$21:$C$39,2,FALSE) -> Формат входных данных не JSON | J69: Отсутствует двоеточие внутри пары ключ-значение | K69: 1 | L69: ="Testing/Data_to_import/"&LEFT(D69,SEARCH(" ",D69)-1)&"/d"&B69&".json" -> Testing/Data_to_import/PATCH/d5.json | M69: ="curl -X PATCH -d ""@"&L69&""" 0.0.0.0:8080/imports/2/citizens/1" -> curl -X PATCH -d "@Testing/Data_to_import/PATCH/d5.json" 0.0.0.0:8080/imports/2/citizens/1 | N69: 400 | O69: =LOGS!F69 -> 400 | P69: =IF(O69=N69,"OK","FAIL") -> OK | Q69: =LOGS!G69 -> Import data is not in JSON format | R69: =LOGS!H69 -> 0.000871
A70: 69 | B70: 6 | C70: ="R"&VLOOKUP(D70,'Описание значений'!$B$4:$C$8,2,FALSE)&"_G"&F70&"_N"&TEXT(G70,"00") -> R02_G01t01_N03 | D70: PATCH data | E70: 01 | F70: 01t01 | G70: 3 | H70: =VLOOKUP(E70,'Описание значений'!$B$11:$C$18,2,FALSE) -> Общая ошибка в формате входных данных | I70: =VLOOKUP(F70,'Описание значений'!$B$21:$C$39,2,FALSE) -> Формат входных данных не JSON | J70: Лишняя запятая в конце списка | K70: 1 | L70: ="Testing/Data_to_import/"&LEFT(D70,SEARCH(" ",D70)-1)&"/d"&B70&".json" -> Testing/Data_to_import/PATCH/d6.json | M70: ="curl -X PATCH -d ""@"&L70&""" 0.0.0.0:8080/imports/2/citizens/1" -> curl -X PATCH -d "@Testing/Data_to_import/PATCH/d6.json" 0.0.0.0:8080/imports/2/citizens/1 | N70: 400 | O70: =LOGS!F70 -> 400 | P70: =IF(O70=N70,"OK","FAIL") -> OK | Q70: =LOGS!G70 -> Import data is not in JSON format | R70: =LOGS!H70 -> 0.001024
A71: 70 | B71: 7 | C71: ="R"&VLOOKUP(D71,'Описание значений'!$B$4:$C$8,2,FALSE)&"_G"&F71&"_N"&TEXT(G71,"00") -> R02_G01t02_N01 | D71: PATCH data | E71: 01 | F71: 01t02 | G71: 1 | H71: =VLOOKUP(E71,'Описание значений'!$B$11:$C$18,2,FALSE) -> Общая ошибка в формате входных данных | I71: =VLOOKUP(F71,'Описание значений'!$B$21:$C$39,2,FALSE) -> Ошибка в структуре входных данных | J71: Присутствует дублирование ключа town | K71: 1 | L71: ="Testing/Data_to_import/"&LEFT(D71,SEARCH(" ",D71)-1)&"/d"&B71&".json" -> Testing/Data_to_import/PATCH/d7.json | M71: ="curl -X PATCH -d ""@"&L71&""" 0.0.0.0:8080/imports/2/citizens/1" -> curl -X PATCH -d "@Testing/Data_to_import/PATCH/d7.json" 0.0.0.0:8080/imports/2/citizens/1 | N71: 400 | O71: =LOGS!F71 -> 400 | P71: =IF(O71=N71,"OK","FAIL") -> OK | Q71: =LOGS!G71 -> Import data has duplicate keys | R71: =LOGS!H71 -> 0.000972
A72: 71 | B72: 8 | C72: ="R"&VLOOKUP(D72,'Описание значений'!$B$4:$C$8,2,FALSE)&"_G"&F72&"_N"&TEXT(G72,"00") -> R02_G01t02_N02 | D72: PATCH data | E72: 01 | F72: 01t02 | G72: 2 | H72: =VLOOKUP(E72,'Описание значений'!$B$11:$C$18,2,FALSE) -> Общая ошибка в формате входных данных | I72: =VLOOKUP(F72,'Описание значений'!$B$21:$C$39,2,FALSE) -> Ошибка в структуре входных данных | J72: Отсутствуют данные | K72: 1 | L72: ="Testing/Data_to_import/"&LEFT(D72,SEARCH(" ",D72)-1)&"/d"&B72&".json" -> Testing/Data_to_import/PATCH/d8.json | M72: ="curl -X PATCH -d ""@"&L72&""" 0.0.0.0:8080/imports/2/citizens/1" -> curl -X PATCH -d "@Testing/Data_to_import/PATCH/d8.json" 0.0.0.0:8080/imports/2/citizens/1 | N72: 400 | O72: =LOGS!F72 -> 400 | P72: =IF(O72=N72,"OK","FAIL") -> OK | Q72: =LOGS!G72 -> No valid key in import data | R72: =LOGS!H72 -> 0.000989
A73: 72 | B73: 9 | C73: ="R"&VLOOKUP(D73,'Описание значений'!$B$4:$C$8,2,FALSE)&"_G"&F73&"_N"&TEXT(G73,"00") -> R02_G02t03_N01 | D73: PATCH data | E73: 02 | F73: 02t03 | G73: 1 | H73: =VLOOKUP(E73,'Описание значений'!$B$11:$C$18,2,FALSE) -> Нет необходимых полей во входных данных | I73: =VLOOKUP(F73,'Описание значений'!$B$21:$C$39,2,FALSE) -> Отсутствуют все или несколько полей и есть неописанные | J73: Неописанное поле child в данных | K73: 1 | L73: ="Testing/Data_to_import/"&LEFT(D73,SEARCH(" ",D73)-1)&"/d"&B73&".json" -> Testing/Data_to_import/PATCH/d9.json | M73: ="curl -X PATCH -d ""@"&L73&""" 0.0.0.0:8080/imports/2/citizens/1" -> curl -X PATCH -d "@Testing/Data_to_import/PATCH/d9.json" 0.0.0.0:8080/imports/2/citizens/1 | N73: 400 | O73: =LOGS!F73 -> 400 | P73: =IF(O73=N73,"OK","FAIL") -> OK | Q73: =LOGS!G73 -> One or more extra fields in import data - key child | R73: =LOGS!H73 -> 0.001002
A74: 73 | B74: 10 | C74: ="R"&VLOOKUP(D74,'Описание значений'!$B$4:$C$8,2,FALSE)&"_G"&F74&"_N"&TEXT(G74,"00") -> R02_G02t03_N02 | D74: PATCH data | E74: 02 | F74: 02t03 | G74: 2 | H74: =VLOOKUP(E74,'Описание значений'!$B$11:$C$18,2,FALSE) -> Нет необходимых полей во входных данных | I74: =VLOOKUP(F74,'Описание значений'!$B$21:$C$39,2,FALSE) -> Отсутствуют все или несколько полей и есть неописанные | J74: Поле citizen_id в данных | K74: 1 | L74: ="Testing/Data_to_import/"&LEFT(D74,SEARCH(" ",D74)-1)&"/d"&B74&".json" -> Testing/Data_to_import/PATCH/d10.json | M74: ="curl -X PATCH -d ""@"&L74&""" 0.0.0.0:8080/imports/2/citizens/1" -> curl -X PATCH -d "@Testing/Data_to_import/PATCH/d10.json" 0.0.0.0:8080/imports/2/citizens/1 | N74: 400 | O74: =LOGS!F74 -> 400 | P74: =IF(O74=N74,"OK","FAIL") -> OK | Q74: =LOGS!G74 -> One or more extra fields in import data - key citizen_id | R74: =LOGS!H74 -> 0.001087
A75: 74 | B75: 11 | C75: ="R"&VLOOKUP(D75,'Описание значений'!$B$4:$C$8,2,FALSE)&"_G"&F75&"_N"&TEXT(G75,"00") -> R02_G03t01_N01 | D75: PATCH data | E75: 03 | F75: 03t01 | G75: 1 | H75: =VLOOKUP(E75,'Описание значений'!$B$11:$C$18,2,FALSE) -> Лишние поля во входных данных | I75: =VLOOKUP(F75,'Описание значений'!$B$21:$C$39,2,FALSE) -> Лишние поля во входных данных | J75: Поля child и citizen_id во входных данных | K75: 1 | L75: ="Testing/Data_to_import/"&LEFT(D75,SEARCH(" ",D75)-1)&"/d"&B75&".json" -> Testing/Data_to_import/PATCH/d11.json | M75: ="curl -X PATCH -d ""@"&L75&""" 0.0.0.0:8080/imports/2/citizens/1" -> curl -X PATCH -d "@Testing/Data_to_import/PATCH/d11.json" 0.0.0.0:8080/imports/2/citizens/1 | N75: 400 | O75: =LOGS!F75 -> 400 | P75: =IF(O75=N75,"OK","FAIL") -> OK | Q75: =LOGS!G75 -> One or more extra fields in import data - key citizen_id | R75: =LOGS!H75 -> 0.0011
A76: 75 | B76: 12 | C76: ="R"&VLOOKUP(D76,'Описание значений'!$B$4:$C$8,2,FALSE)&"_G"&F76&"_N"&TEXT(G76,"00") -> R02_G03t01_N02 | D76: PATCH data | E76: 03 | F76: 03t01 | G76: 2 | H76: =VLOOKUP(E76,'Описание значений'!$B$11:$C$18,2,FALSE) -> Лишние поля во входных данных | I76: =VLOOKUP(F76,'Описание значений'!$B$21:$C$39,2,FALSE) -> Лишние поля во входных данных | J76: Неописанное поле child в данных (присутствуют также relatives и street) | K76: 1 | L76: ="Testing/Data_to_import/"&LEFT(D76,SEARCH(" ",D76)-1)&"/d"&B76&".json" -> Testing/Data_to_import/PATCH/d12.json | M76: ="curl -X PATCH -d ""@"&L76&""" 0.0.0.0:8080/imports/2/citizens/1" -> curl -X PATCH -d "@Testing/Data_to_import/PATCH/d12.json" 0.0.0.0:8080/imports/2/citizens/1 | N76: 400 | O76: =LOGS!F76 -> 400 | P76: =IF(O76=N76,"OK","FAIL") -> OK | Q76: =LOGS!G76 -> One or more extra fields in import data - key child | R76: =LOGS!H76 -> 0.00082
A77: 76 | B77: 13 | C77: ="R"&VLOOKUP(D77,'Описание значений'!$B$4:$C$8,2,FALSE)&"_G"&F77&"_N"&TEXT(G77,"00") -> R02_G04t01_N01 | D77: PATCH data | E77: 04 | F77: 04t01 | G77: 1 | H77: =VLOOKUP(E77,'Описание значений'!$B$11:$C$18,2,FALSE) -> Ошибка в значениях во входных данных | I77: =VLOOKUP(F77,'Описание значений'!$B$21:$C$39,2,FALSE) -> Присутствует отрицательное число | J77: apartment=-1 | K77: 1 | L77: ="Testing/Data_to_import/"&LEFT(D77,SEARCH(" ",D77)-1)&"/d"&B77&".json" -> Testing/Data_to_import/PATCH/d13.json | M77: ="curl -X PATCH -d ""@"&L77&""" 0.0.0.0:8080/imports/2/citizens/1" -> curl -X PATCH -d "@Testing/Data_to_import/PATCH/d13.json" 0.0.0.0:8080/imports/2/citizens/1 | N77: 400 | O77: =LOGS!F77 -> 400 | P77: =IF(O77=N77,"OK","FAIL") -> OK | Q77: =LOGS!G77 -> One or more values in import data are invalid - key apartment | R77: =LOGS!H77 -> 0.001021
A78: 77 | B78: 14 | C78: ="R"&VLOOKUP(D78,'Описание значений'!$B$4:$C$8,2,FALSE)&"_G"&F78&"_N"&TEXT(G78,"00") -> R02_G04t02_N01 | D78: PATCH data | E78: 04 | F78: 04t02 | G78: 1 | H78: =VLOOKUP(E78,'Описание значений'!$B$11:$C$18,2,FALSE) -> Ошибка в значениях во входных данных | I78: =VLOOKUP(F78,'Описание значений'!$B$21:$C$39,2,FALSE) -> Неверные длина строки/числовое значение | J78: Длина строки street больше 256 | K78: 1 | L78: ="Testing/Data_to_import/"&LEFT(D78,SEARCH(" ",D78)-1)&"/d"&B78&".json" -> Testing/Data_to_import/PATCH/d14.json | M78: ="curl -X PATCH -d ""@"&L78&""" 0.0.0.0:8080/imports/2/citizens/1" -> curl -X PATCH -d "@Testing/Data_to_import/PATCH/d14.json" 0.0.0.0:8080/imports/2/citizens/1 | N78: 400 | O78: =LOGS!F78 -> 400 | P78: =IF(O78=N78,"OK","FAIL") -> OK | Q78: =LOGS!G78 -> One or more values in import data are invalid - key street | R78: =LOGS!H78 -> 0.000736
A79: 78 | B79: 15 | C79: ="R"&VLOOKUP(D79,'Описание значений'!$B$4:$C$8,2,FALSE)&"_G"&F79&"_N"&TEXT(G79,"00") -> R02_G04t03_N01 | D79: PATCH data | E79: 04 | F79: 04t03 | G79: 1 | H79: =VLOOKUP(E79,'Описание значений'!$B$11:$C$18,2,FALSE) -> Ошибка в значениях во входных данных | I79: =VLOOKUP(F79,'Описание значений'!$B$21:$C$39,2,FALSE) -> Дата не является валидной | J79: Дата 29.02.2019 | K79: 1 | L79: ="Testing/Data_to_import/"&LEFT(D79,SEARCH(" ",D79)-1)&"/d"&B79&".json" -> Testing/Data_to_import/PATCH/d15.json | M79: ="curl -X PATCH -d ""@"&L79&""" 0.0.0.0:8080/imports/2/citizens/1" -> curl -X PATCH -d "@Testing/Data_to_import/PATCH/d15.json" 0.0.0.0:8080/imports/2/citizens/1 | N79: 400 | O79: =LOGS!F79 -> 400 | P79: =IF(O79=N79,"OK","FAIL") -> OK | Q79: =LOGS!G79 -> birth_date is invaild or has incorrect format, must be dd.mm.yyyy | R79: =LOGS!H79 -> 0.001187
... A84: 83 | B84: 20 | C84: ="R"&VLOOKUP(D84,'Описание значений'!$B$4:$C$8,2,FALSE)&"_G"&F84&"_N"&TEXT(G84,"00") -> R02_G05t02_N01 | D84: PATCH data | E84: 05 | F84: 05t02 | G84: 1 | H84: =VLOOKUP(E84,'Описание значений'!$B$11:$C$18,2,FALSE) -> Ошибка в форматах во входных данных | I84: =VLOOKUP(F84,'Описание значений'!$B$21:$C$39,2,FALSE) -> Формат даты неверный (не ДД.ММ.ГГГГ) | J84: Дата 14/02/1487 | K84: 1 | L84: ="Testing/Data_to_import/"&LEFT(D84,SEARCH(" ",D84)-1)&"/d"&B84&".json" -> Testing/Data_to_import/PATCH/d20.json | M84: ="curl -X PATCH -d ""@"&L84&""" 0.0.0.0:8080/imports/2/citizens/1" -> curl -X PATCH -d "@Testing/Data_to_import/PATCH/d20.json" 0.0.0.0:8080/imports/2/citizens/1 | N84: 400 | O84: =LOGS!F84 -> 400 | P84: =IF(O84=N84,"OK","FAIL") -> OK | Q84: =LOGS!G84 -> birth_date is invaild or has incorrect format, must be dd.mm.yyyy | R84: =LOGS!H84 -> 0.000978
A85: 84 | B85: 21 | C85: ="R"&VLOOKUP(D85,'Описание значений'!$B$4:$C$8,2,FALSE)&"_G"&F85&"_N"&TEXT(G85,"00") -> R02_G06t01_N01 | D85: PATCH data | E85: 06 | F85: 06t01 | G85: 1 | H85: =VLOOKUP(E85,'Описание значений'!$B$11:$C$18,2,FALSE) -> Ошибка в строке запроса | I85: =VLOOKUP(F85,'Описание значений'!$B$21:$C$39,2,FALSE) -> Отсутствует указанный import_id | J85: import_id=-4 | K85: 1 | L85: ="Testing/Data_to_import/"&LEFT(D85,SEARCH(" ",D85)-1)&"/d"&B85&".json" -> Testing/Data_to_import/PATCH/d21.json | M85: ="curl -X PATCH -d ""@"&L85&""" 0.0.0.0:8080/imports/-4/citizens/1" -> curl -X PATCH -d "@Testing/Data_to_import/PATCH/d21.json" 0.0.0.0:8080/imports/-4/citizens/1 | N85: 400 | O85: =LOGS!F85 -> 400 | P85: =IF(O85=N85,"OK","FAIL") -> OK | Q85: =LOGS!G85 -> Invalid import_id | R85: =LOGS!H85 -> 0.00173
A86: 85 | B86: 22 | C86: ="R"&VLOOKUP(D86,'Описание значений'!$B$4:$C$8,2,FALSE)&"_G"&F86&"_N"&TEXT(G86,"00") -> R02_G06t01_N02 | D86: PATCH data | E86: 06 | F86: 06t01 | G86: 2 | H86: =VLOOKUP(E86,'Описание значений'!$B$11:$C$18,2,FALSE) -> Ошибка в строке запроса | I86: =VLOOKUP(F86,'Описание значений'!$B$21:$C$39,2,FALSE) -> Отсутствует указанный import_id | J86: import_id=0 | K86: 1 | L86: ="Testing/Data_to_import/"&LEFT(D86,SEARCH(" ",D86)-1)&"/d"&B86&".json" -> Testing/Data_to_import/PATCH/d22.json | M86: ="curl -X PATCH -d ""@"&L86&""" 0.0.0.0:8080/imports/0/citizens/1" -> curl -X PATCH -d "@Testing/Data_to_import/PATCH/d22.json" 0.0.0.0:8080/imports/0/citizens/1 | N86: 400 | O86: =LOGS!F86 -> 400 | P86: =IF(O86=N86,"OK","FAIL") -> OK | Q86: =LOGS!G86 -> Invalid import_id | R86: =LOGS!H86 -> 0.000703
A87: 86 | B87: 23 | C87: ="R"&VLOOKUP(D87,'Описание значений'!$B$4:$C$8,2,FALSE)&"_G"&F87&"_N"&TEXT(G87,"00") -> R02_G06t01_N03 | D87: PATCH data | E87: 06 | F87: 06t01 | G87: 3 | H87: =VLOOKUP(E87,'Описание значений'!$B$11:$C$18,2,FALSE) -> Ошибка в строке запроса | I87: =VLOOKUP(F87,'Описание значений'!$B$21:$C$39,2,FALSE) -> Отсутствует указанный import_id | J87: import_id=555 | K87: 1 | L87: ="Testing/Data_to_import/"&LEFT(D87,SEARCH(" ",D87)-1)&"/d"&B87&".json" -> Testing/Data_to_import/PATCH/d23.json | M87: ="curl -X PATCH -d ""@"&L87&""" 0.0.0.0:8080/imports/555/citizens/1" -> curl -X PATCH -d "@Testing/Data_to_import/PATCH/d23.json" 0.0.0.0:8080/imports/555/citizens/1 | N87: 400 | O87: =LOGS!F87 -> 400 | P87: =IF(O87=N87,"OK","FAIL") -> OK | Q87: =LOGS!G87 -> Invalid import_id | R87: =LOGS!H87 -> 0.001659
A88: 87 | B88: 24 | C88: ="R"&VLOOKUP(D88,'Описание значений'!$B$4:$C$8,2,FALSE)&"_G"&F88&"_N"&TEXT(G88,"00") -> R02_G06t02_N01 | D88: PATCH data | E88: 06 | F88: 06t02 | G88: 1 | H88: =VLOOKUP(E88,'Описание значений'!$B$11:$C$18,2,FALSE) -> Ошибка в строке запроса | I88: =VLOOKUP(F88,'Описание значений'!$B$21:$C$39,2,FALSE) -> Отсутствует указанный citizen_id | J88: citizen_id=-8 | K88: 1 | L88: ="Testing/Data_to_import/"&LEFT(D88,SEARCH(" ",D88)-1)&"/d"&B88&".json" -> Testing/Data_to_import/PATCH/d24.json | M88: ="curl -X PATCH -d ""@"&L88&""" 0.0.0.0:8080/imports/2/citizens/-8" -> curl -X PATCH -d "@Testing/Data_to_import/PATCH/d24.json" 0.0.0.0:8080/imports/2/citizens/-8 | N88: 400 | O88: =LOGS!F88 -> 400 | P88: =IF(O88=N88,"OK","FAIL") -> OK | Q88: =LOGS!G88 -> Invalid citizen_id | R88: =LOGS!H88 -> 0.001864
...

Sheet LOGS
A1: N | B1: starting_time | C1: request | D1: ending_time | E1: duration | F1: response_status | G1: response_text | H1: duration_in_seconds | K1: starting_time | L1: request | M1: ending_time | N1: duration | O1: response_status | P1: response_text
A2: 1 | B2: 2019-08-23 13:12:07.067636 | C2: <Request 'http://0.0.0.0:8080/imports' [POST]> | D2: 2019-08-23 13:12:07.103307 | E2: 0:00:00.035671 | F2: 201 | G2: {'import_id': 1} | H2: =SUBSTITUTE(MID(E2,7,10),".",",")+0 -> 0.035671 | K2: 2019-08-23 13:12:07.067636 | L2: <Request 'http://0.0.0.0:8080/imports' [POST]> | M2: 2019-08-23 13:12:07.103307 | N2: 0:00:00.035671 | O2: 201 | P2: {'import_id': 1}
A3: 2 | B3: 2019-08-23 13:12:12.732847 | C3: <Request 'http://0.0.0.0:8080/imports' [POST]> | D3: 2019-08-23 13:12:12.776207 | E3: 0:00:00.043360 | F3: 201 | G3: {'import_id': 2} | H3: =SUBSTITUTE(MID(E3,7,10),".",",")+0 -> 0.04336 | K3: 2019-08-23 13:12:12.732847 | L3: <Request 'http://0.0.0.0:8080/imports' [POST]> | M3: 2019-08-23 13:12:12.776207 | N3: 0:00:00.043360 | O3: 201 | P3: {'import_id': 2}
A4: 3 | B4: 2019-08-23 13:12:17.465704 | C4: <Request 'http://0.0.0.0:8080/imports' [POST]> | D4: 2019-08-23 13:12:17.533728 | E4: 0:00:00.068024 | F4: 201 | G4: {'import_id': 3} | H4: =SUBSTITUTE(MID(E4,7,10),".",",")+0 -> 0.068024 | K4: 2019-08-23 13:12:17.465704 | L4: <Request 'http://0.0.0.0:8080/imports' [POST]> | M4: 2019-08-23 13:12:17.533728 | N4: 0:00:00.068024 | O4: 201 | P4: {'import_id': 3}
A5: 4 | B5: 2019-08-23 13:12:21.457257 | C5: <Request 'http://0.0.0.0:8080/imports' [POST]> | D5: 2019-08-23 13:12:21.593162 | E5: 0:00:00.135905 | F5: 201 | G5: {'import_id': 4} | H5: =SUBSTITUTE(MID(E5,7,10),".",",")+0 -> 0.135905 | K5: 2019-08-23 13:12:21.457257 | L5: <Request 'http://0.0.0.0:8080/imports' [POST]> | M5: 2019-08-23 13:12:21.593162 | N5: 0:00:00.135905 | O5: 201 | P5: {'import_id': 4}
A6: 5 | B6: 2019-08-23 13:12:25.560879 | C6: <Request 'http://0.0.0.0:8080/imports' [POST]> | D6: 2019-08-23 13:12:26.321475 | E6: 0:00:00.760596 | F6: 201 | G6: {'import_id': 5} | H6: =SUBSTITUTE(MID(E6,7,10),".",",")+0 -> 0.760596 | K6: 2019-08-23 13:12:25.560879 | L6: <Request 'http://0.0.0.0:8080/imports' [POST]> | M6: 2019-08-23 13:12:26.321475 | N6: 0:00:00.760596 | O6: 201 | P6: {'import_id': 5}
A7: 6 | B7: 2019-08-23 13:12:32.006398 | C7: <Request 'http://0.0.0.0:8080/imports' [POST]> | D7: 2019-08-23 13:12:35.317915 | E7: 0:00:03.311517 | F7: 201 | G7: {'import_id': 6} | H7: =SUBSTITUTE(MID(E7,7,10),".",",")+0 -> 3.311517 | K7: 2019-08-23 13:12:32.006398 | L7: <Request 'http://0.0.0.0:8080/imports' [POST]> | M7: 2019-08-23 13:12:35.317915 | N7: 0:00:03.311517 | O7: 201 | P7: {'import_id': 6}
A8: 7 | B8: 2019-08-23 13:13:19.149577 | C8: <Request 'http://0.0.0.0:8080/imports' [POST]> | D8: 2019-08-23 13:13:19.150601 | E8: 0:00:00.001024 | F8: 400 | G8: Import data is not in JSON format | H8: =SUBSTITUTE(MID(E8,7,10),".",",")+0 -> 0.001024 | K8: 2019-08-23 13:13:19.149577 | L8: <Request 'http://0.0.0.0:8080/imports' [POST]> | M8: 2019-08-23 13:13:19.150601 | N8: 0:00:00.001024 | O8: 400 | P8: Import data is not in JSON format
A9: 8 | B9: 2019-08-23 13:13:20.663180 | C9: <Request 'http://0.0.0.0:8080/imports' [POST]> | D9: 2019-08-23 13:13:20.663974 | E9: 0:00:00.000794 | F9: 400 | G9: Import data is not in JSON format | H9: =SUBSTITUTE(MID(E9,7,10),".",",")+0 -> 0.000794 | K9: 2019-08-23 13:13:20.663180 | L9: <Request 'http://0.0.0.0:8080/imports' [POST]> | M9: 2019-08-23 13:13:20.663974 | N9: 0:00:00.000794 | O9: 400 | P9: Import data is not in JSON format
A10: 9 | B10: 2019-08-23 13:13:22.178472 | C10: <Request 'http://0.0.0.0:8080/imports' [POST]> | D10: 2019-08-23 13:13:22.179469 | E10: 0:00:00.000997 | F10: 400 | G10: Import data is not in JSON format | H10: =SUBSTITUTE(MID(E10,7,10),".",",")+0 -> 0.000997 | K10: 2019-08-23 13:13:22.178472 | L10: <Request 'http://0.0.0.0:8080/imports' [POST]> | M10: 2019-08-23 13:13:22.179469 | N10: 0:00:00.000997 | O10: 400 | P10: Import data is not in JSON format
A11: 10 | B11: 2019-08-23 13:13:23.694864 | C11: <Request 'http://0.0.0.0:8080/imports' [POST]> | D11: 2019-08-23 13:13:23.695878 | E11: 0:00:00.001014 | F11: 400 | G11: Import data has more than 1 key (should be only "citizens") | H11: =SUBSTITUTE(MID(E11,7,10),".",",")+0 -> 0.001014 | K11: 2019-08-23 13:13:23.694864 | L11: <Request 'http://0.0.0.0:8080/imports' [POST]> | M11: 2019-08-23 13:13:23.695878 | N11: 0:00:00.001014 | O11: 400 | P11: Import data has more than 1 key (should be only "citizens")
A12: 11 | B12: 2019-08-23 13:13:25.212806 | C12: <Request 'http://0.0.0.0:8080/imports' [POST]> | D12: 2019-08-23 13:13:25.213997 | E12: 0:00:00.001191 | F12: 400 | G12: Import data has no "citizens" key | H12: =SUBSTITUTE(MID(E12,7,10),".",",")+0 -> 0.001191 | K12: 2019-08-23 13:13:25.212806 | L12: <Request 'http://0.0.0.0:8080/imports' [POST]> | M12: 2019-08-23 13:13:25.213997 | N12: 0:00:00.001191 | O12: 400 | P12: Import data has no "citizens" key
A13: 12 | B13: 2019-08-23 13:13:26.726954 | C13: <Request 'http://0.0.0.0:8080/imports' [POST]> | D13: 2019-08-23 13:13:26.728106 | E13: 0:00:00.001152 | F13: 400 | G13: Import data has duplicate keys | H13: =SUBSTITUTE(MID(E13,7,10),".",",")+0 -> 0.001152 | K13: 2019-08-23 13:13:26.726954 | L13: <Request 'http://0.0.0.0:8080/imports' [POST]> | M13: 2019-08-23 13:13:26.728106 | N13: 0:00:00.001152 | O13: 400 | P13: Import data has duplicate keys
... A84: 83 | B84: 2019-08-23 13:15:14.577357 | C84: <Request 'http://0.0.0.0:8080/imports/2/citizens/1' [PATCH]> | D84: 2019-08-23 13:15:14.578335 | E84: 0:00:00.000978 | F84: 400 | G84: birth_date is invaild or has incorrect format, must be dd.mm.yyyy | H84: =SUBSTITUTE(MID(E84,7,10),".",",")+0 -> 0.000978 | K84: 2019-08-23 13:15:14.577357 | L84: <Request 'http://0.0.0.0:8080/imports/2/citizens/1' [PATCH]> | M84: 2019-08-23 13:15:14.578335 | N84: 0:00:00.000978 | O84: 400 | P84: birth_date is invaild or has incorrect format, must be dd.mm.yyyy
A85: 84 | B85: 2019-08-23 09:47:22.806798 | C85: <Request 'http://0.0.0.0:8080/imports/-4/citizens/1' [PATCH]> | D85: 2019-08-23 09:47:22.808528 | E85: 0:00:00.001730 | F85: 400 | G85: Invalid import_id | H85: =SUBSTITUTE(MID(E85,7,10),".",",")+0 -> 0.00173
A86: 85 | B86: 2019-08-23 09:47:27.858636 | C86: <Request 'http://0.0.0.0:8080/imports/0/citizens/1' [PATCH]> | D86: 2019-08-23 09:47:27.859339 | E86: 0:00:00.000703 | F86: 400 | G86: Invalid import_id | H86: =SUBSTITUTE(MID(E86,7,10),".",",")+0 -> 0.000703
A87: 86 | B87: 2019-08-23 09:47:33.663330 | C87: <Request 'http://0.0.0.0:8080/imports/555/citizens/1' [PATCH]> | D87: 2019-08-23 09:47:33.664989 | E87: 0:00:00.001659 | F87: 400 | G87: Invalid import_id | H87: =SUBSTITUTE(MID(E87,7,10),".",",")+0 -> 0.001659
A88: 87 | B88: 2019-08-23 09:47:43.731347 | C88: <Request 'http://0.0.0.0:8080/imports/2/citizens/-8' [PATCH]> | D88: 2019-08-23 09:47:43.733211 | E88: 0:00:00.001864 | F88: 400 | G88: Invalid citizen_id | H88: =SUBSTITUTE(MID(E88,7,10),".",",")+0 -> 0.001864
A89: 88 | B89: 2019-08-23 09:47:49.069995 | C89: <Request 'http://0.0.0.0:8080/imports/2/citizens/123' [PATCH]> | D89: 2019-08-23 09:47:49.071890 | E89: 0:00:00.001895 | F89: 400 | G89: Invalid citizen_id | H89: =SUBSTITUTE(MID(E89,7,10),".",",")+0 -> 0.001895
A90: 89 | B90: 2019-08-23 09:48:26.695909 | C90: <Request 'http://0.0.0.0:8080/imports/3/citizens' [GET]> | D90: 2019-08-23 09:48:26.705932 | E90: 0:00:00.010023 | F90: 200 | G90: longer than 300 symbols | H90: =SUBSTITUTE(MID(E90,7,10),".",",")+0 -> 0.010023
A91: 90 | B91: 2019-08-23 09:48:34.151398 | C91: <Request 'http://0.0.0.0:8080/imports/50/citizens' [GET]> | D91: 2019-08-23 09:48:34.153314 | E91: 0:00:00.001916 | F91: 400 | G91: Invalid import_id | H91: =SUBSTITUTE(MID(E91,7,10),".",",")+0 -> 0.001916
A92: 91 | B92: 2019-08-23 09:48:43.694239 | C92: <Request 'http://0.0.0.0:8080/imports/3/citizens/birthdays' [GET]> | D92: 2019-08-23 09:48:43.782625 | E92: 0:00:00.088386 | F92: 200 | G92: longer than 300 symbols | H92: =SUBSTITUTE(MID(E92,7,10),".",",")+0 -> 0.088386
A93: 92 | B93: 2019-08-23 09:48:51.999146 | C93: <Request 'http://0.0.0.0:8080/imports/16/citizens/birthdays' [GET]> | D93: 2019-08-23 09:48:52.000963 | E93: 0:00:00.001817 | F93: 400 | G93: Invalid import_id | H93: =SUBSTITUTE(MID(E93,7,10),".",",")+0 -> 0.001817
A94: 93 | B94: 2019-08-23 09:49:12.158947 | C94: <Request 'http://0.0.0.0:8080/imports/3/towns/stat/percentile/age' [GET]> | D94: 2019-08-23 09:49:12.192704 | E94: 0:00:00.033757 | F94: 200 | G94: longer than 300 symbols | H94: =SUBSTITUTE(MID(E94,7,10),".",",")+0 -> 0.033757
A95: 94 | B95: 2019-08-23 09:49:19.839274 | C95: <Request 'http://0.0.0.0:8080/imports/-5/towns/stat/percentile/age' [GET]> | D95: 2019-08-23 09:49:19.841075 | E95: 0:00:00.001801 | F95: 400 | G95: Invalid import_id | H95: =SUBSTITUTE(MID(E95,7,10),".",",")+0 -> 0.001801
